2025-03-20 09:43:17,674 - __main__ - ERROR - Excepción no capturada
Traceback (most recent call last):
  File "D:\Workplace\HdfullScrappers\.venv\Lib\site-packages\selenium\webdriver\common\driver_finder.py", line 64, in _binary_paths
    raise ValueError(f"The path is not a valid file: {path}")
ValueError: The path is not a valid file: chromedriver.exe

The above exception was the direct cause of the following exception:

Traceback (most recent call last):
  File "d:\Workplace\HdfullScrappers\.venv\direct_dw_series_scraper.py", line 57, in <module>
    driver = webdriver.Chrome(service=service, options=options)
             ^^^^^^^^^^^^^^^^^^^^^^^^^^^^^^^^^^^^^^^^^^^^^^^^^^
  File "D:\Workplace\HdfullScrappers\.venv\Lib\site-packages\selenium\webdriver\chrome\webdriver.py", line 45, in __init__
    super().__init__(
  File "D:\Workplace\HdfullScrappers\.venv\Lib\site-packages\selenium\webdriver\chromium\webdriver.py", line 50, in __init__
    if finder.get_browser_path():
       ^^^^^^^^^^^^^^^^^^^^^^^^^
  File "D:\Workplace\HdfullScrappers\.venv\Lib\site-packages\selenium\webdriver\common\driver_finder.py", line 47, in get_browser_path
    return self._binary_paths()["browser_path"]
           ^^^^^^^^^^^^^^^^^^^^
  File "D:\Workplace\HdfullScrappers\.venv\Lib\site-packages\selenium\webdriver\common\driver_finder.py", line 78, in _binary_paths
    raise NoSuchDriverException(msg) from err
selenium.common.exceptions.NoSuchDriverException: Message: Unable to obtain driver for chrome; For documentation on this error, please visit: https://www.selenium.dev/documentation/webdriver/troubleshooting/errors/driver_location

